<?xml version="1.0" ?>
<!-- =================================================================================== -->
<!-- |    This document was autogenerated by xacro from human.urdf.xacro               | -->
<!-- |    EDITING THIS FILE BY HAND IS NOT RECOMMENDED                                 | -->
<!-- =================================================================================== -->
<robot name="human_wb">
  <link name="world"/>
  <joint name="world_to_human" type="fixed">
    <origin rpy="1.57 -0 0" xyz="0. 0. 0."/>
    <axis xyz="0 0 1"/>
    <parent link="world"/>
    <child link="pelvis"/>
  </joint>
  <material name="body_color">
    
    <color rgba="0.005 0.005 0.005 0.6"/>
  </material>
  <link name="pelvis">
    <inertial>
      <mass value="13.3963"/>
      <origin rpy="0 -0 0" xyz="-0.07526 -0.027216 -0.000567"/>
      <inertia ixx="0.134392" ixy="0.0068219" ixz="0.00172127" iyy="0.134423" iyz="0.000558921" izz="0.120176"/>
    </inertial>
    <visual>
      <origin rpy="0 0 0" xyz="0 0 0"/>
      <geometry>
        <mesh filename="meshes/pelvis_mesh.STL" scale="0.006 0.0055 0.0055"/>
      </geometry>
      <material name="body_color">
        
        <color rgba="0 1 1 0.5"/>
      </material>
    </visual>

    <collision>
      <origin xyz="0 0 0" rpy="0 0 0"/>
      <geometry>
        <!-- <mesh filename="meshes/capsule.stl" scale="1.0 1.0 1.0"/> -->
        <mesh filename="meshes/pelvis_mesh.STL" scale="0.006 0.0055 0.0055"/>
       <!-- <sphere radius="0.05"/> -->
      </geometry>
    </collision>

  </link>
  <joint name="middle_lumbar_Z" type="revolute">
    <origin rpy="0 -0 0" xyz="0 0 0"/>
    <axis xyz="0 0 1"/>
    <parent link="pelvis"/>
    <child link="torso_z"/>
    <limit effort="0" lower="-3.14159" upper="0.785398" velocity="0"/>
  </joint>
  <link name="torso_z"/>
  <joint name="middle_lumbar_Y" type="revolute">
    <origin rpy="0 -0 0" xyz="0 0 0"/>
    <axis xyz="1 0 0"/>
    <parent link="torso_z"/>
    <child link="torso"/>
    <limit effort="0" lower="-0.785398" upper="0.785398" velocity="0"/>
  </joint>
  <link name="torso">
    <inertial>
      <mass value="28.6794"/>
      <origin rpy="0 -0 0" xyz="0 0.188511 -0.00135864"/>
      <inertia ixx="1.60287" ixy="0.0400354" ixz="0.000330871" iyy="0.360371" iyz="-0.00436749" izz="1.44797"/>
    </inertial>
    <visual>
      <origin rpy="0 -0 0" xyz="0. 0. 0."/>
      <geometry>
        <mesh filename="meshes/abdomen_mesh.STL" scale="0.0055 0.0055 0.0055"/>
        <!--<box size="0.15 0.161217 0.198658" />-->
      </geometry>
      <material name="body_color">
        
        <color rgba="0 1 1 0.5"/>
      </material>
    </visual>
    <visual>
      <origin rpy="0 0 0" xyz="0. 0. 0."/>
      <geometry>
        <!--<box size="0.15 0.356643 0.329994" />-->
        <mesh filename="meshes/torso_mesh.STL" scale="0.0065 0.0065 0.0065"/>
      </geometry>
      <material name="body_color">
        
        <color rgba="0.2 0.2 0.2 0.2"/>
      </material>
    </visual>

    <collision>
      <origin xyz="0 0 0" rpy="0 0 0"/>
      <geometry>
        <!-- <mesh filename="meshes/capsule.stl" scale="1.0 1.0 1.0"/> -->
        <mesh filename="meshes/torso_mesh.STL" scale="0.0065 0.0065 0.0065"/>
       <!-- <sphere radius="0.05"/> -->
      </geometry>
    </collision>
  </link>

  <link name="head">
  <inertial>
    <mass value="8.0"/>
    <origin rpy="0 -0 0" xyz="0 0 0"/>
    <inertia ixx="0.032" ixy="0.0" ixz="0.0" iyy="0.032" iyz="0.0" izz="0.032"/>
  </inertial>

    <visual>
      <origin rpy="0 -0 0" xyz="0. 0. 0."/>
      <geometry>
      <sphere radius="0.1"/>
        <!-- <mesh filename="meshes/abdomen_mesh.STL" scale="0.0055 0.0055 0.0055"/> -->
        <!--<box size="0.15 0.161217 0.198658" />-->
      </geometry>
      <material name="head_color">
        <color rgba="0 1 0 0.8"/>
      </material>
    </visual>

    <collision>
      <origin xyz="0 0 0" rpy="0 0 0"/>
      <geometry>
        <sphere radius="0.15"/>
       <!-- <sphere radius="0.05"/> -->
      </geometry>
    </collision>
  </link>

  <link name="head_Z_prismatic_link"/>
  <link name="head_Y_prismatic_link"/>
  <link name="head_X_prismatic_link"/>
  <link name="head_Z_revolute_link"/>
  <link name="head_Y_revolute_link"/>
  <joint name="head_Z_prismatic" type="prismatic">
    <origin rpy="0 -0 0" xyz="0.00 0.61 0.0"/>
    <axis xyz="0 0 1"/>
    <parent link="torso"/>
    <child link="head_Z_prismatic_link"/>
    <limit effort="0" lower="-0.1" upper="0.1" velocity="0"/>
  </joint>
  <joint name="head_Y_prismatic" type="prismatic">
    <origin rpy="0 -0 0" xyz="0.00 0.0 0.0"/>
    <axis xyz="0 1 0"/>
    <parent link="head_Z_prismatic_link"/>
    <child link="head_Y_prismatic_link"/>
    <limit effort="0" lower="-0.03" upper="0.03" velocity="0"/>
  </joint>
  <joint name="head_X_prismatic" type="prismatic">
    <origin rpy="0 -0 0" xyz="0.00 0.0 0.0"/>
    <axis xyz="1 0 0"/>
    <parent link="head_Y_prismatic_link"/>
    <child link="head_X_prismatic_link"/>
    <limit effort="0" lower="-0.1" upper="0.1" velocity="0"/>
  </joint>
  <joint name="head_Z_revolute" type="revolute">
    <origin rpy="0 -0 0" xyz="0.0 0.0 0.0"/>
    <axis xyz="0 0 1"/>
    <parent link="head_X_prismatic_link"/>
    <child link="head_Z_revolute_link"/>
    <limit effort="0" lower="-0.5" upper="0.5" velocity="0"/>
  </joint>
  <joint name="head_Y_revolute" type="revolute">
    <origin rpy="0 -0 0" xyz="0.0 0.0 0.0"/>
    <axis xyz="0 1 0"/>
    <parent link="head_Z_revolute_link"/>
    <child link="head_Y_revolute_link"/>
    <limit effort="0" lower="-0.5" upper="0.5" velocity="0"/>
  </joint>
  <joint name="head_X_revolute" type="revolute">
    <origin rpy="0 -0 0" xyz="0.0 0.0 0.0"/>
    <axis xyz="1 0 0"/>
    <parent link="head_Y_revolute_link"/>
    <child link="head"/>
    <limit effort="0" lower="-0.5" upper="0.5" velocity="0"/>
  </joint>

  <joint name="right_shoulder_Z" type="revolute">
    <origin rpy="0 -0 0" xyz="0.00805 0.4067 0.2037"/>
    <axis xyz="0 0 1"/>
    <parent link="torso"/>
    <child link="upperarm_z_R"/>
    <limit effort="0" lower="-2.0944" upper="0.392699" velocity="0"/>
  </joint>
  <link name="upperarm_z_R">
    <visual>
      <origin rpy="0 0 0" xyz="0. 0. 0."/>
      <geometry>
        <mesh filename="meshes/shoulder_mesh.STL" scale="0.0055 0.0055 0.0055"/>
      </geometry>
      <material name="body_color">
        
        <color rgba="0 1 1 0.5"/>
      </material>
    </visual>
    <collision>
      <origin xyz="0 0 0" rpy="0 0 0"/>
      <geometry>
        <!-- <mesh filename="meshes/capsule.stl" scale="1.0 1.0 1.0"/> -->
        <mesh filename="meshes/shoulder_mesh.STL" scale="0.0055 0.0055 0.0055"/>
       <!-- <sphere radius="0.05"/> -->
      </geometry>
    </collision>
  </link>

  <joint name="right_shoulder_X" type="revolute">
    <origin rpy="0 -0 0" xyz="0 0 0"/>
    <axis xyz="1 0 0"/>
    <parent link="upperarm_z_R"/>
    <child link="upperarm_x_R"/>
    <limit effort="0" lower="-3.14159" upper="1.0472" velocity="0"/>
  </joint>
  <link name="upperarm_x_R"/>
  <joint name="right_shoulder_Y" type="revolute">
    <origin rpy="0 -0 0" xyz="0 0 0"/>
    <axis xyz="0 1 0"/>
    <parent link="upperarm_x_R"/>
    <child link="upperarmR"/>
    <limit effort="0" lower="-1.5708" upper="3.14159" velocity="0"/>
  </joint>
  <link name="upperarmR">
    <inertial>
      <mass value="2.26416"/>
      <origin rpy="0 -0 0" xyz="0.00506736 -0.135693 -0.00872712"/>
      <inertia ixx="0.0569524" ixy="0.00200545" ixz="0.000261627" iyy="0.00326316" iyz="0.000351349" izz="0.0578968"/>
    </inertial>
    <visual>
      <origin rpy="0.0 0 0" xyz="0. 0. 0."/>
      <geometry>
        <mesh filename="meshes/upperarm_mesh.STL" scale="0.0063 0.0060 0.007"/>
      </geometry>
      <material name="body_color">
        
        <color rgba="0 1 1 0.5"/>
      </material>
    </visual>

    <collision>
      <origin xyz="0 0 0" rpy="0 0 0"/>
      <geometry>
        <!-- <mesh filename="meshes/capsule.stl" scale="1.0 1.0 1.0"/> -->
        <mesh filename="meshes/upperarm_mesh.STL" scale="0.0063 0.0060 0.007"/>
       <!-- <sphere radius="0.05"/> -->
      </geometry>
    </collision>
  </link>
  <joint name="right_elbow_Z" type="revolute">
    <origin rpy="0 -0 0" xyz="0 -0.2737 0"/>
    <axis xyz="0 0 1"/>
    <parent link="upperarmR"/>
    <child link="lowerarm_z"/>
    <limit effort="0" lower="0" upper="2.74889" velocity="0"/>
  </joint>
  <link name="lowerarm_z">
    <visual>
      <origin rpy="0 0 0" xyz="0. 0. 0."/>
      <geometry>
        <mesh filename="meshes/elbow_mesh.STL" scale="0.0055 0.0055 0.0055"/>
      </geometry>
      <material name="body_color">
        
        <color rgba="0 1 1 0.5"/>
      </material>
    </visual>

    <collision>
      <origin xyz="0 0 0" rpy="0 0 0"/>
      <geometry>
        <!-- <mesh filename="meshes/capsule.stl" scale="1.0 1.0 1.0"/> -->
        <mesh filename="meshes/elbow_mesh.STL" scale="0.0055 0.0055 0.0055"/>
       <!-- <sphere radius="0.05"/> -->
      </geometry>
    </collision>
  </link>
  <joint name="right_elbow_Y" type="revolute">
    <origin rpy="0 -0 0" xyz="0 0 0"/>
    <axis xyz="0 1 0"/>
    <parent link="lowerarm_z"/>
    <child link="lowerarmR"/>
    <limit effort="0" lower="-1.5708" upper="1.5708" velocity="0"/>
  </joint>
  <link name="lowerarmR">
    <inertial>
      <mass value="1.60378"/>
      <origin rpy="0 -0 0" xyz="-0.00373932 -0.119946 0.00316404"/>
      <inertia ixx="0.0334927" ixy="0.000129905" ixz="3.22441e-05" iyy="0.00164405" iyz="0.000661733" izz="0.033499"/>
    </inertial>
    <visual>
      <origin rpy="0.0 0 0" xyz="0. 0. 0."/>
      <geometry>
        <mesh filename="meshes/lowerarm_mesh.STL" scale="0.0060 0.0060 0.0060"/>
      </geometry>
      <material name="body_color">
        
        <color rgba="0 1 1 0.5"/>
      </material>

    <collision>
      <origin xyz="0 0 0" rpy="0 0 0"/>
      <geometry>
        <!-- <mesh filename="meshes/capsule.stl" scale="1.0 1.0 1.0"/> -->
        <mesh filename="meshes/lowerarm_mesh.STL" scale="0.0060 0.0060 0.0060"/>
       <!-- <sphere radius="0.05"/> -->
      </geometry>
    </collision>

    </visual>
  </link>

  <joint name="handR_fixed_joint" type="fixed">
    <origin rpy="0 -0 0" xyz="0 -0.34 0"/>
    <parent link="lowerarmR"/>
    <child link="handR"/>
  </joint>

  <link name="handR">
  <inertial>
    <mass value="8.0"/>
    <origin rpy="0 -0 0" xyz="0 0 0"/>
    <inertia ixx="0.02048" ixy="0.0" ixz="0.0" iyy="0.02048" iyz="0.0" izz="0.02048"/>
  </inertial>

    <visual>
      <origin rpy="0 -0 0" xyz="0. 0. 0."/>
      <geometry>
      <sphere radius="0.08"/>
        <!-- <mesh filename="meshes/abdomen_mesh.STL" scale="0.0055 0.0055 0.0055"/> -->
        <!--<box size="0.15 0.161217 0.198658" />-->
      </geometry>
      <material name="hand_color">
        
        <color rgba="1 0 0 1"/>
      </material>
    </visual>

    <collision>
      <origin xyz="0 0 0" rpy="0 0 0"/>
      <geometry>
        <sphere radius="0.12"/>
       <!-- <sphere radius="0.05"/> -->
      </geometry>
    </collision>
  </link>




  <joint name="left_shoulder_Z" type="revolute">
    <origin rpy="0 -0 0" xyz="0.00805 0.4067 -0.2037"/>
    <axis xyz="0 0 1"/>
    <parent link="torso"/>
    <child link="upperarm_z_L"/>
    <limit effort="0" lower="-2.0944" upper="0.392699" velocity="0"/>
  </joint>
  <link name="upperarm_z_L">
    <visual>
      <origin rpy="0 0 0" xyz="0. 0. 0."/>
      <geometry>
        <mesh filename="meshes/shoulder_mesh.STL" scale="0.0055 0.0055 0.0055"/>
      </geometry>
      <material name="body_color">
        
        <color rgba="0 1 1 0.5"/>
      </material>
    <collision>
      <origin xyz="0 0 0" rpy="0 0 0"/>
      <geometry>
        <!-- <mesh filename="meshes/capsule.stl" scale="1.0 1.0 1.0"/> -->
        <mesh filename="meshes/shoulder_mesh.STL" scale="0.0055 0.0055 0.0055"/>
       <!-- <sphere radius="0.05"/> -->
      </geometry>
    </collision>

    </visual>


  </link>
  <joint name="left_shoulder_X" type="revolute">
    <origin rpy="0 -0 0" xyz="0 0 0"/>
    <axis xyz="1 0 0"/>
    <parent link="upperarm_z_L"/>
    <child link="upperarm_x_L"/>
    <limit effort="0" lower="-3.14159" upper="1.0472" velocity="0"/>
  </joint>
  <link name="upperarm_x_L"/>
  <joint name="left_shoulder_Y" type="revolute">
    <origin rpy="0 -0 0" xyz="0 0 0"/>
    <axis xyz="0 1 0"/>
    <parent link="upperarm_x_L"/>
    <child link="upperarmL"/>
    <limit effort="0" lower="-1.5708" upper="3.14159" velocity="0"/>
  </joint>
  <link name="upperarmL">
    <inertial>
      <mass value="2.26416"/>
      <origin rpy="0 -0 0" xyz="0.00506736 -0.135693 0.00872712"/>
      <inertia ixx="0.0569524" ixy="0.00200545" ixz="-0.000261627" iyy="0.00326316" iyz="-0.000351349" izz="0.0578968"/>
    </inertial>
    <visual>
      <origin rpy="0.0 0 0" xyz="0. 0. 0."/>
      <geometry>
        <mesh filename="meshes/upperarm_mesh.STL" scale="0.0063 0.0060 0.007"/>
      </geometry>
      <material name="body_color"/>
    </visual>

    <collision>
      <origin xyz="0 0 0" rpy="0 0 0"/>
      <geometry>
        <!-- <mesh filename="meshes/capsule.stl" scale="1.0 1.0 1.0"/> -->
        <mesh filename="meshes/upperarm_mesh.STL" scale="0.0063 0.0060 0.007"/>
       <!-- <sphere radius="0.05"/> -->
      </geometry>
    </collision>
  </link>
  <joint name="left_elbow_Z" type="revolute">
    <origin rpy="0 -0 0" xyz="0 -0.2737 0"/>
    <axis xyz="0 0 1"/>
    <parent link="upperarmL"/>
    <child link="lowerarm_z_L"/>
    <limit effort="0" lower="0" upper="2.74889" velocity="0"/>
  </joint>
  <link name="lowerarm_z_L">
    <visual>
      <origin rpy="0 0 0" xyz="0. 0. 0."/>
      <geometry>
        <mesh filename="meshes/elbow_mesh.STL" scale="0.0055 0.0055 0.0055"/>
      </geometry>
      <material name="body_color">
        
        <color rgba="0 1 1 0.5"/>
      </material>

    <collision>
      <origin xyz="0 0 0" rpy="0 0 0"/>
      <geometry>
        <!-- <mesh filename="meshes/capsule.stl" scale="1.0 1.0 1.0"/> -->
        <mesh filename="meshes/elbow_mesh.STL" scale="0.0055 0.0055 0.0055"/>
       <!-- <sphere radius="0.05"/> -->
      </geometry>
    </collision>
    </visual>
  </link>
  <joint name="left_elbow_Y" type="revolute">
    <origin rpy="0 -0 0" xyz="0 0 0"/>
    <axis xyz="0 1 0"/>
    <parent link="lowerarm_z_L"/>
    <child link="lowerarmL"/>
    <limit effort="0" lower="-1.5708" upper="1.5708" velocity="0"/>
  </joint>
  <link name="lowerarmL">
    <inertial>
      <mass value="1.60378"/>
      <origin rpy="0 -0 0" xyz="-0.00373932 -0.119946 -0.00316404"/>
      <inertia ixx="0.0334927" ixy="0.000129905" ixz="-3.22441e-05" iyy="0.00164405" iyz="-0.000661733" izz="0.033499"/>
    </inertial>
    <visual>
      <origin rpy="0.0 0 0" xyz="0. 0. 0."/>
      <geometry>
        <mesh filename="meshes/lowerarm_mesh.STL" scale="0.0060 0.0060 0.0060"/>
      </geometry>
      <material name="body_color">
        
        <color rgba="0 1 1 0.5"/>
      </material>
    </visual>

    <collision>
      <origin xyz="0 0 0" rpy="0 0 0"/>
      <geometry>
        <!-- <mesh filename="meshes/capsule.stl" scale="1.0 1.0 1.0"/> -->
        <mesh filename="meshes/lowerarm_mesh.STL" scale="0.0060 0.0060 0.0060"/>
       <!-- <sphere radius="0.05"/> -->
      </geometry>
    </collision>
  </link>

  <joint name="handL_fixed_joint" type="fixed">
    <origin rpy="0 -0 0" xyz="0 -0.34 0"/>
    <parent link="lowerarmL"/>
    <child link="handL"/>
  </joint>

  <link name="handL">
  <inertial>
    <mass value="8.0"/>
    <origin rpy="0 -0 0" xyz="0 0 0"/>
    <inertia ixx="0.02048" ixy="0.0" ixz="0.0" iyy="0.02048" iyz="0.0" izz="0.02048"/>
  </inertial>

    <visual>
      <origin rpy="0 -0 0" xyz="0. 0. 0."/>
      <geometry>
      <sphere radius="0.08"/>
        <!-- <mesh filename="meshes/abdomen_mesh.STL" scale="0.0055 0.0055 0.0055"/> -->
        <!--<box size="0.15 0.161217 0.198658" />-->
      </geometry>
      <material name="hand_color">
        
        <color rgba="1 0 0 1"/>
      </material>
    </visual>

    <collision>
      <origin xyz="0 0 0" rpy="0 0 0"/>
      <geometry>
        <sphere radius="0.12"/>
       <!-- <sphere radius="0.05"/> -->
      </geometry>
    </collision>
  </link>


  <joint name="right_hip_Z" type="revolute">
    <origin rpy="0 -0 0" xyz="0.053375 -0.0749 0.079975"/>
    <axis xyz="0 0 1"/>
    <parent link="pelvis"/>
    <child link="thigh_z"/>
    <limit effort="0" lower="-0.785398" upper="3.14159" velocity="0"/>
  </joint>
  <link name="thigh_z"/>
  <joint name="right_hip_X" type="revolute">
    <origin rpy="0 -0 0" xyz="0 0 0"/>
    <axis xyz="1 0 0"/>
    <parent link="thigh_z"/>
    <child link="thigh_x"/>
    <limit effort="0" lower="-0.392699" upper="1.5708" velocity="0"/>
  </joint>
  <link name="thigh_x">
  </link>
  <joint name="right_hip_Y" type="revolute">
    <origin rpy="0 -0 0" xyz="0 0 0"/>
    <axis xyz="0 1 0"/>
    <parent link="thigh_x"/>
    <child link="thighR"/>
    <limit effort="0" lower="-1.5708" upper="1.5708" velocity="0"/>
  </joint>
  <link name="thighR">
    <inertial>
      <mass value="11.6038"/>
      <origin rpy="0 -0 0" xyz="-0.0180072 -0.188417 -0.0144936"/>
      <inertia ixx="0.602628" ixy="-0.0284023" ixz="-0.00213314" iyy="0.0565628" iyz="-0.0207203" izz="0.617159"/>
    </inertial>
    <visual>
      <origin rpy="0.0 0 0" xyz="0. 0. 0."/>
      <geometry>
        <mesh filename="meshes/upperleg_mesh.STL" scale="0.0063 0.0065 0.007"/>
      </geometry>
      <material name="body_color">
        
        <color rgba="0 1 1 0.5"/>
      </material>
    </visual>

    <collision>
      <origin xyz="0 0 0" rpy="0 0 0"/>
      <geometry>
        <!-- <mesh filename="meshes/capsule.stl" scale="1.0 1.0 1.0"/> -->
        <mesh filename="meshes/upperleg_mesh.STL" scale="0.0063 0.0065 0.007"/>
       <!-- <sphere radius="0.05"/> -->
      </geometry>
    </collision>
  </link>
  <joint name="right_knee_Z" type="revolute">
    <origin rpy="0 -0 0" xyz="0 -0.427 0"/>
    <axis xyz="0 0 1"/>
    <parent link="thighR"/>
    <child link="shankR"/>
    <limit effort="0" lower="0" upper="2.74889" velocity="0"/>
  </joint>
  <link name="shankR">
    <inertial>
      <mass value="4.52832"/>
      <origin rpy="0 -0 0" xyz="-0.0211334 -0.180515 0.00308196"/>
      <inertia ixx="0.21642" ixy="-0.0158706" ixz="0.00064606" iyy="0.0108434" iyz="0.00392376" izz="0.2184"/>
    </inertial>
    <visual>
      <origin rpy="0.0 0 0" xyz="0. 0. 0."/>
      <geometry>
        <mesh filename="meshes/lowerleg_mesh.STL" scale="0.0063 0.0065 0.007"/>
      </geometry>
      <material name="body_color">
        
        <color rgba="0 1 1 0.5"/>
      </material>
    </visual>
    <visual>
      <origin rpy="0.0 0 0" xyz="0. 0. 0."/>
      <geometry>
        <mesh filename="meshes/knee_mesh.STL" scale="0.006 0.006 0.006"/>
      </geometry>
      <material name="body_color">
        
        <color rgba="0 1 1 0.5"/>
      </material>
    </visual>

    <collision>
      <origin xyz="0 0 0" rpy="0 0 0"/>
      <geometry>
        <!-- <mesh filename="meshes/capsule.stl" scale="1.0 1.0 1.0"/> -->
        <mesh filename="meshes/lowerleg_mesh.STL" scale="0.0063 0.0065 0.007"/>
       <!-- <sphere radius="0.05"/> -->
      </geometry>
    </collision>

  </link>
  <joint name="right_ankle_Z" type="revolute">
    <origin rpy="0 -0 0" xyz="0 -0.42805 0"/>
    <axis xyz="0 0 1"/>
    <parent link="shankR"/>
    <child link="footR"/>
    <limit effort="0" lower="-1.0472" upper="0.392699" velocity="0"/>
  </joint>

  <link name="footR">
    <inertial>
      <mass value="1.13208"/>
      <origin rpy="0 -0 0" xyz="0.0709326 -0.0281187 0.0048042"/>
      <inertia ixx="0.00201519" ixy="0.00291119" ixz="-0.000112291" iyy="0.011149" iyz="0.00015293" izz="0.0117988"/>
    </inertial>
    <visual>
      <origin rpy="0 0 0" xyz="0. 0. 0."/>
      <geometry>
        <mesh filename="meshes/foot_mesh.STL" scale="0.0060 0.0060 0.0060"/>
        <!--<box size="0.03 0.085239 0.06" />-->
      </geometry>
      <material name="body_color">
        <color rgba="0 1 1 0.5"/>
      </material>
    </visual>
    <collision>
      <origin xyz="0 0 0" rpy="0 0 0"/>
      <geometry>
        <!-- <mesh filename="meshes/capsule.stl" scale="1.0 1.0 1.0"/> -->
        <mesh filename="meshes/foot_mesh.STL" scale="0.0060 0.0060 0.0060"/>
       <!-- <sphere radius="0.05"/> -->
      </geometry>
    </collision>
  </link>
  <joint name="left_hip_Z" type="revolute">
    <origin rpy="0 -0 0" xyz="0.053375 -0.0749 -0.079975"/>
    <axis xyz="0 0 1"/>
    <parent link="pelvis"/>
    <child link="thigh_z_L"/>
    <limit effort="0" lower="-0.785398" upper="3.14159" velocity="0"/>
  </joint>
  <link name="thigh_z_L"/>
  <joint name="left_hip_X" type="revolute">
    <origin rpy="0 -0 0" xyz="0 0 0"/>
    <axis xyz="1 0 0"/>
    <parent link="thigh_z_L"/>
    <child link="thigh_x_L"/>
    <limit effort="0" lower="-0.392699" upper="1.5708" velocity="0"/>
  </joint>
  <link name="thigh_x_L">
  </link>
  <joint name="left_hip_Y" type="revolute">
    <origin rpy="0 -0 0" xyz="0 0 0"/>
    <axis xyz="0 1 0"/>
    <parent link="thigh_x_L"/>
    <child link="thighL"/>
    <limit effort="0" lower="-1.5708" upper="1.5708" velocity="0"/>
  </joint>
  <link name="thighL">
    <inertial>
      <mass value="11.6038"/>
      <origin rpy="0 -0 0" xyz="-0.0180072 -0.188417 0.0144936"/>
      <inertia ixx="0.602628" ixy="-0.0284023" ixz="0.00213314" iyy="0.0565628" iyz="0.0207203" izz="0.617159"/>
    </inertial>
    <visual>
      <origin rpy="0.0 0 0" xyz="0 0. 0."/>
      <geometry>
        <mesh filename="meshes/upperleg_mesh.STL" scale="0.0063 0.0065 0.007"/>
      </geometry>
      <material name="body_color">
        
        <color rgba="0 1 1 0.5"/>
      </material>
    </visual>

    <collision>
      <origin xyz="0 0 0" rpy="0 0 0"/>
      <geometry>
        <!-- <mesh filename="meshes/capsule.stl" scale="1.0 1.0 1.0"/> -->
        <mesh filename="meshes/upperleg_mesh.STL" scale="0.0063 0.0065 0.007"/>
       <!-- <sphere radius="0.05"/> -->
      </geometry>
    </collision>

  </link>
  <joint name="left_knee_Z" type="revolute">
    <origin rpy="0 -0 0" xyz="0 -0.427 0"/>
    <axis xyz="0 0 1"/>
    <parent link="thighL"/>
    <child link="shankL"/>
    <limit effort="0" lower="0" upper="2.74889" velocity="0"/>
  </joint>
  <link name="shankL">
    <inertial>
      <mass value="4.52832"/>
      <origin rpy="0 -0 0" xyz="-0.0211334 -0.180515 -0.00308196"/>
      <inertia ixx="0.21642" ixy="-0.0158706" ixz="-0.00064606" iyy="0.0108434" iyz="-0.00392376" izz="0.2184"/>
    </inertial>
    <visual>
      <origin rpy="0.0 0 0" xyz="0. 0. 0."/>
      <geometry>
        <mesh filename="meshes/lowerleg_mesh.STL" scale="0.0063 0.0065 0.007"/>
      </geometry>
      <material name="body_color">
        
        <color rgba="0 1 1 0.5"/>
      </material>
    </visual>
        <visual>
      <origin rpy="0.0 0 0" xyz="0. 0. 0."/>
      <geometry>
        <mesh filename="meshes/knee_mesh.STL" scale="0.006 0.006 0.006"/>
      </geometry>
      <material name="body_color">
        
        <color rgba="0 1 1 0.5"/>
      </material>
    </visual>

    <collision>
      <origin xyz="0 0 0" rpy="0 0 0"/>
      <geometry>
        <!-- <mesh filename="meshes/capsule.stl" scale="1.0 1.0 1.0"/> -->
        <mesh filename="meshes/lowerleg_mesh.STL" scale="0.0063 0.0065 0.007"/>
       <!-- <sphere radius="0.05"/> -->
      </geometry>
    </collision>
  </link>
  <joint name="left_ankle_Z" type="revolute">
    <origin rpy="0 -0 0" xyz="0 -0.42805 0"/>
    <axis xyz="0 0 1"/>
    <parent link="shankL"/>
    <child link="footL"/>
    <limit effort="0" lower="-0.392699" upper="1.0472" velocity="0"/>
  </joint>



  <link name="footL">
    <inertial>
      <mass value="1.13208"/>
      <origin rpy="0 -0 0" xyz="0.0709326 -0.0281187 -0.0048042"/>
      <inertia ixx="0.00201519" ixy="0.00291119" ixz="0.000112291" iyy="0.011149" iyz="-0.00015293" izz="0.0117988"/>
    </inertial>
    <visual>
      <origin rpy="0 0 0" xyz="0. 0. 0."/>
      <geometry>
        <!-- <mesh filename="meshes/capsule.stl" scale="1.2 1.2 1.2"/> -->
        <mesh filename="meshes/foot_mesh.STL" scale="0.0060 0.0060 0.0060"/>
        <!--<box size="0.03 0.085239 0.06" />-->
      </geometry>
      <material name="body_color">
        <color rgba="0 1 1 0.5"/>
      </material>
    </visual>


    <collision>
      <origin xyz="0 0 0" rpy="0 0 0"/>
      <geometry>
        <!-- <mesh filename="meshes/capsule.stl" scale="1.0 1.0 1.0"/> -->
        <mesh filename="meshes/foot_mesh.STL" scale="0.0060 0.0060 0.0060"/>
       <!-- <sphere radius="0.05"/> -->
      </geometry>
    </collision>

  </link>

</robot>

<!-- 
URDF STRUCTURE
root Link: world has 1 child(ren)
    child(1):  pelvis
        child(1):  thigh_z_L
            child(1):  thigh_x_L
                child(1):  thighL
                    child(1):  shankL
                        child(1):  footL
        child(2):  torso_z
            child(1):  torso
                child(1):  upperarm_z_L
                    child(1):  upperarm_x_L
                        child(1):  upperarmL
                            child(1):  lowerarm_z_L
                                child(1):  lowerarmL
                child(2):  upperarm_z_R
                    child(1):  upperarm_x_R
                        child(1):  upperarmR
                            child(1):  lowerarm_z
                                child(1):  lowerarmR
        child(3):  thigh_z
            child(1):  thigh_x
                child(1):  thighR
                    child(1):  shankR
                        child(1):  footR -->

